Workbook

Sheet Protfolio
F2: =B4 | G2: Beginning Balance | I2: 1037509.3 | J2: YTD | K2: =B4 | L2: $ Gain/Loss w/o Dis | N2: =IF(I3>0,(IT263+IV263)-I2,0)
F3: =B4 | G3: Ending Balance | I3: =IT263 | J3: =IT265 | K3: =B4 | L3: $ Gain/Loss w Dist. | N3: =IF(I3>0,IT263/I2,0) | O3: =300*43.8 | FD3: Spinoff (GEV) on 4/2/24
B4: ='Investment Analysis'!B3 | C4: Portfolio Data | F4: =B4 | G4: YTD Gain/Loss | I4: =IF(IT263>0,I3-I2,0) | J4: =J3+J5-I2 | K4: Current | L4: $ Gain/Loss w Dist. | N4: =J3-I2 | P4: Current Investment Position Results | V4: =B4 | W4: Beginning Value
F5: =B4 | G5: Distrabution Taken | I5: =IV263 | J5: =IU265 | K5: =B4 | L5: % Gain/Loss w/o Dis. | N5: =IF(J3>0,((J3+J5)-I2)/I2,0) | P5: 1 | Q5: ='Investment Analysis'!Y10 | R5: =IF(P264>0,P264/$IT$7,0) | S5: =P5+1 | T5: =22468+'Investment Analysis'!AH4 | U5: =IF(S264>0,S264/$IT$7,0) | V5: =S5+1 | W5: =17715+'Investment Analysis'!AO4 | X5: =IF(V264>0,V264/$IT$7,0) | Y5: =V5+1 | Z5: =9976+'Investment Analysis'!GM4 | AA5: =IF(Y264>0,Y264/$IT$7,0) | AB5: =Y5+1 | AC5: =2663+'Investment Analysis'!AV4 | AD5: =IF(AB264>0,AB264/$IT$7,0) | AE5: =AB5+1 | AF5: =22429+'Investment Analysis'!BC4 | AG5: =IF(AE264>0,AE264/$IT$7,0) | AH5: =AE5+1 | AI5: ='Investment Analysis'!BJ4 | AJ5: =IF(AH264>0,AH264/$IT$7,0) | AK5: =AH5+1 | AL5: =18847+'Investment Analysis'!BQ4 | AM5: =IF(AK264>0,AK264/$IT$7,0) | AN5: =AK5+1 | AO5: =14640+'Investment Analysis'!BX4 | AP5: =IF(AN264>0,AN264/$IT$7,0) | AQ5: =AN5+1 | AR5: ='Investment Analysis'!GT4 | AS5: =IF(AQ264>0,AQ264/$IT$7,0) | AT5: =AQ5+1 | AU5: =27227+'Investment Analysis'!CL4 | AV5: =IF(AT264>0,AT264/$IT$7,0) | AW5: =AT5+1 | AX5: =19243+'Investment Analysis'!CS4 | AY5: =IF(AW264>0,AW264/$IT$7,0) | AZ5: =AW5+1 | BA5: =16827+'Investment Analysis'!CZ4 | BB5: =IF(AZ264>0,AZ264/$IT$7,0) | BC5: =AZ5+1 | BD5: =10041+'Investment Analysis'!DG4 | BE5: =IF(BC264>0,BC264/$IT$7,0) | BF5: =BC5+1 | BG5: =4195+'Investment Analysis'!DN4 | BH5: =IF(BF264>0,BF264/$IT$7,0) | BI5: =BF5+1 | BJ5: =2554+'Investment Analysis'!EB4 | BK5: =IF(BI264>0,BI264/$IT$7,0) | BL5: =BI5+1 | BM5: =4401+'Investment Analysis'!EI4 | BN5: =IF(BL264>0,BL264/$IT$7,0) | BO5: =BL5+1 | BP5: ='Investment Analysis'!DU4 | BQ5: =IF(BO264>0,BO264/$IT$7,0) | BR5: =BO5+1 | BS5: =5659+'Investment Analysis'!EP4 | BT5: =IF(BR264>0,BR264/$IT$7,0) | BU5: =BR5+1 | BV5: =14858+'Investment Analysis'!EW4 | BW5: =IF(BU264>0,BU264/$IT$7,0) | BX5: =BU5+1 | BY5: ='Investment Analysis'!FD4 | BZ5: =IF(BX264>0,BX264/$IT$7,0) | CA5: =BX5+1 | CB5: =3200+'Investment Analysis'!FK4 | CC5: =IF(CA264>0,CA264/$IT$7,0) | CD5: =CA5+1 | CE5: =19032+'Investment Analysis'!FR4 | CF5: =IF(CD264>0,CD264/$IT$7,0) | CG5: =CD5+1 | CH5: =5077+'Investment Analysis'!FY4 | CI5: =IF(CG264>0,CG264/$IT$7,0) | CJ5: =CG5+1 | CK5: ='Investment Analysis'!GF4 | CL5: =IF(CJ264>0,CJ264/$IT$7,0) | CM5: =CJ5+1 | CN5: =4950+'Investment Analysis'!HA4 | CO5: =IF(CM264>0,CM264/$IT$7,0) | CP5: =CM5+1 | CQ5: ='Investment Analysis'!HE5 | CR5: =IF(CP264>0,CP264/$IT$7,0) | CS5: =CP5+1 | CT5: ='Investment Analysis'!HL5 | CU5: =IF(CS264>0,CS264/$IT$7,0) | CV5: =CS5+1 | CW5: ='Investment Analysis'!HZ5 | CX5: =IF(CV264>0,CV264/$IT$7,0) | CY5: =CV5+1 | CZ5: ='Investment Analysis'!IG5 | DA5: =IF(CY264>0,CY264/$IT$7,0) | DB5: =CY5+1 | DC5: ='Investment Analysis'!IN5 | DD5: =IF(DB264>0,DB264/$IT$7,0) | DE5: =DB5+1 | DF5: ='Investment Analysis'!IU5 | DG5: =IF(DE264>0,DE264/$IT$7,0) | DH5: =DE5+1 | DI5: ='Investment Analysis'!JB5 | DJ5: =IF(DH264>0,DH264/$IT$7,0) | DK5: =DH5+1 | DL5: ='Investment Analysis'!JI5 | DM5: =IF(DK264>0,DK264/$IT$7,0) | DN5: =DK5+1 | DO5: ='Investment Analysis'!HS5 | DP5: =IF(DN264>0,DN264/$IT$7,0) | DQ5: =DN5+1 | DR5: ='Investment Analysis'!JP5 | DS5: =IF(DQ264>0,DQ264/$IT$7,0) | DT5: =DQ5+1 | DU5: ='Investment Analysis'!JW5 | DV5: =IF(DT264>0,DT264/$IT$7,0) | DW5: =DT5+1 | DX5: ='Investment Analysis'!KD5 | DY5: =IF(DW264>0,DW264/$IT$7,0) | DZ5: =DW5+1 | EA5: ='Investment Analysis'!KK5 | EB5: =IF(DZ264>0,DZ264/$IT$7,0) | EC5: =DZ5+1 | ED5: ='Investment Analysis'!KR5 | EE5: =IF(EC264>0,EC264/$IT$7,0) | EF5: =EC5+1 | EG5: ='Investment Analysis'!LF5 | EH5: =IF(EF264>0,EF264/$IT$7,0) | EI5: =EF5+1 | EJ5: ='Investment Analysis'!LM5 | EK5: =IF(EI264>0,EI264/$IT$7,0) | EL5: =EI5+1 | EM5: ='Investment Analysis'!LT5 | EN5: =IF(EL264>0,EL264/$IT$7,0) | EO5: =EL5+1 | EP5: ='Investment Analysis'!MA5 | EQ5: =IF(EO264>0,EO264/$IT$7,0) | ER5: =EO5+1 | ES5: ='Investment Analysis'!KY5 | ET5: =IF(ER264>0,ER264/$IT$7,0) | EU5: =ER5+1 | EV5: ='Investment Analysis'!MH5 | EW5: =IF(EU264>0,EU264/$IT$7,0) | EX5: =EU5+1 | EY5: ='Investment Analysis'!MO5 | EZ5: =IF(EX264>0,EX264/$IT$7,0) | FA5: =EX5+1 | FB5: ='Investment Analysis'!MV5 | FC5: =IF(FA264>0,FA264/$IT$7,0) | FD5: =FA5+1 | FE5: ='Investment Analysis'!NC5 | FF5: =IF(FD264>0,FD264/$IT$7,0) | FG5: =FD5+1 | FH5: ='Investment Analysis'!NJ5 | FI5: =IF(FG264>0,FG264/$IT$7,0) | FJ5: =FG5+1 | FK5: ='Investment Analysis'!NQ5 | FL5: =IF(FJ264>0,FJ264/$IT$7,0) | FM5: =FJ5+1 | FN5: ='Investment Analysis'!NX5 | FO5: =IF(FM264>0,FM264/$IT$7,0) | FP5: =FM5+1 | FQ5: ='Investment Analysis'!OE5 | FR5: =IF(FP264>0,FP264/$IT$7,0) | FS5: =FP5+1 | FT5: ='Investment Analysis'!OL5 | FU5: =IF(FS264>0,FS264/$IT$7,0) | FV5: =FS5+1 | FW5: ='Investment Analysis'!OS5 | FX5: =IF(FV264>0,FV264/$IT$7,0) | FY5: =FV5+1 | FZ5: ='Investment Analysis'!OZ5 | GA5: =IF(FY264>0,FY264/$IT$7,0) | GB5: =FY5+1 | GC5: ='Investment Analysis'!PG5 | GD5: =IF(GB264>0,GB264/$IT$7,0) | GE5: =GB5+1 | GF5: ='Investment Analysis'!PU5 | GG5: =IF(GE264>0,GE264/$IT$7,0) | GH5: =GE5+1 | GI5: ='Investment Analysis'!QB5 | GJ5: =IF(GH264>0,GH264/$IT$7,0) | GK5: =GH5+1 | GL5: ='Investment Analysis'!QI5 | GM5: =IF(GK264>0,GK264/$IT$7,0) | GN5: =GK5+1 | GO5: ='Investment Analysis'!QP5 | GP5: =IF(GN264>0,GN264/$IT$7,0) | GQ5: =GN5+1 | GR5: ='Investment Analysis'!QW5 | GS5: =IF(GQ264>0,GQ264/$IT$7,0) | GT5: =GQ5+1 | GU5: ='Investment Analysis'!RD5 | GV5: =IF(GT264>0,GT264/$IT$7,0) | GW5: =GT5+1 | GX5: ='Investment Analysis'!RK5 | GY5: =IF(GW264>0,GW264/$IT$7,0) | GZ5: =GW5+1 | HA5: ='Investment Analysis'!RR5 | HB5: =IF(GZ264>0,GZ264/$IT$7,0) | HC5: =GZ5+1 | HD5: ='Investment Analysis'!RY5 | HE5: =IF(HC264>0,HC264/$IT$7,0) | HF5: =HC5+1 | HG5: ='Investment Analysis'!SF5 | HH5: =IF(HF264>0,HF264/$IT$7,0) | HI5: =HF5+1 | HJ5: ='Investment Analysis'!SM5 | HK5: =IF(HI264>0,HI264/$IT$7,0) | HL5: =HI5+1 | HM5: ='Investment Analysis'!ST5 | HN5: =IF(HL264>0,HL264/$IT$7,0) | HO5: =HL5+1 | HP5: ='Investment Analysis'!TA5 | HQ5: =IF(HO264>0,HO264/$IT$7,0) | HR5: =HO5+1 | HS5: ='Investment Analysis'!TH5 | HT5: =IF(HR264>0,HR264/$IT$7,0) | HU5: =HR5+1 | HV5: ='Investment Analysis'!TO5 | HW5: =IF(HU264>0,HU264/$IT$7,0) | HX5: =HU5+1 | HY5: ='Investment Analysis'!TV5 | HZ5: =IF(HX264>0,HX264/$IT$7,0) | IA5: =HX5+1 | IB5: ='Investment Analysis'!UC5 | IC5: =IF(IA264>0,IA264/$IT$7,0) | ID5: =IA5+1 | IE5: ='Investment Analysis'!UJ5 | IF5: =IF(ID264>0,ID264/$IT$7,0) | IG5: =ID5+1 | IH5: ='Investment Analysis'!UJ5 | II5: =IF(IG264>0,IG264/$IT$7,0) | IJ5: =IG5+1 | IK5: ='Investment Analysis'!UQ3 | IL5: =IF(IJ264>0,IJ264/$IT$7,0) | IM5: =IJ5+1 | IN5: ='Investment Analysis'!UX3 | IO5: =IF(IM264>0,IM264/$IT$7,0)
F6: =B4 | G6: End Bal. w/o Dist. | I6: =IT265+IV265 | J6: =J3+J5 | K6: =B4 | L6: % Gain/Loss w Dist. | N6: =IF(I3>0,((I3-I2)/I2),0) | P6: ='Investment Analysis'!Y6 | S6: ='Investment Analysis'!AC6 | V6: ='Investment Analysis'!AJ7 | Y6: Health Care - Biotech | AB6: ='Investment Analysis'!AQ6 | AE6: ='Investment Analysis'!AX6 | AH6: ='Investment Analysis'!BE6 | AK6: ='Investment Analysis'!BL6 | AN6: ='Investment Analysis'!BS6 | AQ6: ='Investment Analysis'!GO4 | AT6: ='Investment Analysis'!CG6 | AW6: ='Investment Analysis'!CN6 | AZ6: ='Investment Analysis'!CU6 | BC6: ='Investment Analysis'!DB6 | BF6: ='Investment Analysis'!DI6 | BI6: ='Investment Analysis'!DW6 | BL6: ='Investment Analysis'!ED6 | BO6: ='Investment Analysis'!DP6 | BR6: ='Investment Analysis'!EK6 | BU6: ='Investment Analysis'!ER6 | BX6: ='Investment Analysis'!EY6 | CA6: ='Investment Analysis'!FF6 | CD6: ='Investment Analysis'!FM6 | CG6: ='Investment Analysis'!FT6 | CJ6: ='Investment Analysis'!GA6 | CM6: ='Investment Analysis'!GV6 | CP6: ='Investment Analysis'!HD6 | CS6: ='Investment Analysis'!HK6 | CV6: ='Investment Analysis'!HY6 | CY6: ='Investment Analysis'!IF6 | DB6: ='Investment Analysis'!IM6 | DE6: ='Investment Analysis'!IT6 | DH6: ='Investment Analysis'!JA6 | DK6: ='Investment Analysis'!JH6 | DN6: ='Investment Analysis'!HR6 | DQ6: ='Investment Analysis'!JO6 | DT6: ='Investment Analysis'!JV6 | DW6: ='Investment Analysis'!KC6 | DZ6: ='Investment Analysis'!KJ6 | EC6: ='Investment Analysis'!KQ6 | EF6: ='Investment Analysis'!LE6 | EI6: ='Investment Analysis'!LL6 | EL6: ='Investment Analysis'!LS6 | EO6: ='Investment Analysis'!LZ6 | ER6: ='Investment Analysis'!KX6 | EU6: ='Investment Analysis'!MG6 | EX6: ='Investment Analysis'!MN6 | FA6: ='Investment Analysis'!MU6 | FD6: ='Investment Analysis'!NB6 | FG6: ='Investment Analysis'!NI6 | FJ6: ='Investment Analysis'!NP6 | FM6: ='Investment Analysis'!NW6 | FP6: ='Investment Analysis'!OD6 | FS6: ='Investment Analysis'!OK6 | FV6: ='Investment Analysis'!OR6 | FY6: ='Investment Analysis'!OY6 | GB6: ='Investment Analysis'!PF6 | GE6: ='Investment Analysis'!PT6 | GH6: ='Investment Analysis'!QA6 | GK6: ='Investment Analysis'!QH6 | GN6: ='Investment Analysis'!QO6 | GQ6: ='Investment Analysis'!QV6 | GT6: ='Investment Analysis'!RC6 | GW6: ='Investment Analysis'!RJ6 | GZ6: ='Investment Analysis'!RX6 | HC6: ='Investment Analysis'!RX6 | HF6: ='Investment Analysis'!SE6 | HI6: ='Investment Analysis'!SL6 | HL6: ='Investment Analysis'!SS6 | HO6: ='Investment Analysis'!SZ6 | HR6: ='Investment Analysis'!TG6 | HU6: ='Investment Analysis'!TN6 | HX6: ='Investment Analysis'!TU6 | IA6: ='Investment Analysis'!UB6 | ID6: ='Investment Analysis'!UI6 | IG6: ='Investment Analysis'!UP6 | IJ6: ='Investment Analysis'!UW6 | IM6: ='Investment Analysis'!VD6
K7: Current | L7: % Gain/Loss w Dist. | N7: =IF(J3>0,(J3-I2)/I2,0) | P7: Percent of Portfolio | R7: ='Investment Analysis'!AA5 | S7: Percent of Portfolio | U7: ='Investment Analysis'!AH5 | V7: Percent of Portfolio | X7: ='Investment Analysis'!AO5 | Y7: Percent of Portfolio | AA7: ='Investment Analysis'!GM5 | AB7: Percent of Portfolio | AD7: ='Investment Analysis'!AV5 | AE7: Percent of Portfolio | AG7: ='Investment Analysis'!BC5 | AH7: Percent of Portfolio | AJ7: ='Investment Analysis'!BF5 | AK7: Percent of Portfolio | AM7: ='Investment Analysis'!BQ5 | AN7: Percent of Portfolio | AP7: ='Investment Analysis'!BX5 | AQ7: Percent of Portfolio | AS7: =AS5 | AT7: Percent of Portfolio | AV7: ='Investment Analysis'!CL5 | AW7: Percent of Portfolio | AY7: ='Investment Analysis'!CZ5 | AZ7: Percent of Portfolio | BB7: ='Investment Analysis'!DG5 | BC7: Percent of Portfolio | BE7: ='Investment Analysis'!DJ5 | BF7: Percent of Portfolio | BH7: ='Investment Analysis'!DN5 | BI7: Percent of Portfolio | BK7: ='Investment Analysis'!EB5 | BL7: Percent of Portfolio | BN7: ='Investment Analysis'!EI5 | BO7: Percent of Portfolio | BQ7: =BQ5 | BR7: Percent of Portfolio | BT7: ='Investment Analysis'!EP5 | BU7: Percent of Portfolio | BW7: ='Investment Analysis'!EW5 | BX7: Percent of Portfolio | BZ7: ='Investment Analysis'!FD5 | CA7: Percent of Portfolio | CC7: =CC5 | CD7: Percent of Portfolio | CF7: ='Investment Analysis'!FR5 | CG7: Percent of Portfolio | CI7: ='Investment Analysis'!FY5 | CJ7: Percent of Portfolio | CL7: ='Investment Analysis'!GF5 | CM7: Percent of Portfolio | CO7: ='Investment Analysis'!HA5 | CP7: Shares | CQ7: ='Investment Analysis'!HG5 | CR7: =CR5 | CS7: Shares | CT7: ='Investment Analysis'!HN5 | CU7: =CU5 | CV7: Shares | CW7: ='Investment Analysis'!IB5 | CX7: =CX5 | CY7: Shares | CZ7: ='Investment Analysis'!II5 | DA7: =DA5 | DB7: Shares | DC7: ='Investment Analysis'!IP5 | DD7: =DD5 | DE7: Shares | DF7: ='Investment Analysis'!IW5 | DG7: =DG5 | DH7: Shares | DI7: ='Investment Analysis'!JD5 | DJ7: =DJ5 | DK7: Shares | DL7: ='Investment Analysis'!JK5 | DM7: =DM5 | DN7: Shares | DO7: ='Investment Analysis'!HU5 | DP7: =DP5 | DQ7: Shares | DR7: ='Investment Analysis'!JR5 | DS7: =DS5 | DT7: Shares | DU7: ='Investment Analysis'!JY5 | DV7: =DV5 | DW7: Shares | DX7: ='Investment Analysis'!KF5 | DY7: =DY5 | DZ7: Shares | EA7: ='Investment Analysis'!KM5 | EB7: =EB5 | EC7: Shares | ED7: ='Investment Analysis'!KT5 | EE7: =EE5 | EF7: Shares | EG7: ='Investment Analysis'!LH5 | EH7: =EH5 | EI7: Shares | EJ7: ='Investment Analysis'!LO5 | EK7: =EK5 | EL7: Shares | EM7: ='Investment Analysis'!LV5 | EN7: =EN5 | EO7: Shares | EP7: ='Investment Analysis'!MC5 | EQ7: =EQ5 | ER7: Shares | ES7: ='Investment Analysis'!LA5 | ET7: =ET5 | EU7: Shares | EV7: ='Investment Analysis'!MJ5 | EW7: =EW5 | EX7: Shares | EY7: ='Investment Analysis'!MQ5 | EZ7: =EZ5 | FA7: Shares | FB7: ='Investment Analysis'!MX5 | FC7: =FC5 | FD7: Shares | FE7: ='Investment Analysis'!NE5 | FF7: =FF5 | FG7: Shares | FH7: ='Investment Analysis'!NL5 | FI7: =FI5 | FJ7: Shares | FK7: ='Investment Analysis'!NS5 | FL7: =FL5 | FM7: Shares | FN7: ='Investment Analysis'!NZ5 | FO7: =FO5 | FP7: Shares | FQ7: ='Investment Analysis'!NY5 | FR7: =FR5 | FS7: Shares | FT7: ='Investment Analysis'!ON5 | FU7: =FU5 | FV7: Shares | FW7: ='Investment Analysis'!OU5 | FX7: =FX5 | FY7: Shares | FZ7: ='Investment Analysis'!PB5 | GA7: =GA5 | GB7: Shares | GC7: ='Investment Analysis'!PI5 | GD7: =GD5 | GE7: Shares | GF7: ='Investment Analysis'!PW5 | GG7: =GG5 | GH7: Shares | GI7: ='Investment Analysis'!QD5 | GJ7: =GJ5 | GK7: Shares | GL7: ='Investment Analysis'!QK5 | GM7: =GM5 | GN7: Shares | GO7: ='Investment Analysis'!QR5 | GP7: =GP5 | GQ7: Shares | GR7: ='Investment Analysis'!QY5 | GS7: =GS5 | GT7: Shares | GU7: ='Investment Analysis'!RF5 | GV7: =GV5 | GW7: Shares | GX7: ='Investment Analysis'!RM5 | GY7: =GY5 | GZ7: Shares | HA7: ='Investment Analysis'!RT5 | HB7: =HB5 | HC7: Shares | HD7: ='Investment Analysis'!SA5 | HE7: =HE5 | HF7: Shares | HG7: ='Investment Analysis'!SH5 | HH7: =HH5 | HI7: Shares | HJ7: ='Investment Analysis'!SO5 | HK7: =HK5 | HL7: Shares | HM7: ='Investment Analysis'!SV5 | HN7: =HN5 | HO7: Shares | HP7: ='Investment Analysis'!TC5 | HQ7: =HQ5 | HR7: Shares | HS7: ='Investment Analysis'!TJ5 | HT7: =HT5 | HU7: Shares | HV7: ='Investment Analysis'!TQ5 | HW7: =HW5 | HX7: Shares | HY7: ='Investment Analysis'!TX5 | HZ7: =HZ5 | IA7: Shares | IB7: ='Investment Analysis'!UE5 | IC7: =IC5 | ID7: Shares | IE7: ='Investment Analysis'!UL5 | IF7: =IF5 | IG7: Shares | IH7: ='Investment Analysis'!US5 | II7: =II5 | IJ7: Shares | IK7: ='Investment Analysis'!UZ5 | IL7: =IL5 | IM7: Shares | IN7: ='Investment Analysis'!VG5 | IO7: =IO5 | IT7: =IT265
D8: Dow Jones | G8: S&P 500 | J8: Nasdaq | L8: Comp. | M8: Daily | N8: YTD | P8: ='Investment Analysis'!Y7 | S8: ='Investment Analysis'!AC7 | V8: ='Investment Analysis'!AJ7 | Y8: ='Investment Analysis'!GH7 | AB8: ='Investment Analysis'!AQ7 | AE8: ='Investment Analysis'!AX7 | AH8: ='Investment Analysis'!BE7 | AK8: ='Investment Analysis'!BL7 | AN8: ='Investment Analysis'!BS7 | AQ8: ='Investment Analysis'!GO7 | AT8: ='Investment Analysis'!CG7 | AW8: ='Investment Analysis'!CN7 | AZ8: ='Investment Analysis'!CU7 | BC8: ='Investment Analysis'!DB7 | BF8: ='Investment Analysis'!DI7 | BI8: ='Investment Analysis'!DW7 | BL8: ='Investment Analysis'!ED7 | BO8: ='Investment Analysis'!DP7 | BR8: ='Investment Analysis'!EK7 | BU8: ='Investment Analysis'!ER7 | BX8: ='Investment Analysis'!EY7 | CA8: ='Investment Analysis'!FF7 | CD8: ='Investment Analysis'!FM7 | CG8: ='Investment Analysis'!FT7 | CJ8: ='Investment Analysis'!GA7 | CM8: ='Investment Analysis'!GV7 | CP8: ='Investment Analysis'!HD7 | CS8: ='Investment Analysis'!HK7 | CV8: ='Investment Analysis'!HY7 | CY8: ='Investment Analysis'!IF7 | DB8: ='Investment Analysis'!IM7 | DE8: ='Investment Analysis'!IT7 | DH8: ='Investment Analysis'!JA7 | DK8: ='Investment Analysis'!JH7 | DN8: ='Investment Analysis'!HR7 | DQ8: ='Investment Analysis'!JO7 | DT8: ='Investment Analysis'!JV7 | DW8: ='Investment Analysis'!KC7 | DZ8: ='Investment Analysis'!KJ7 | EC8: ='Investment Analysis'!KQ7 | EF8: ='Investment Analysis'!LE7 | EI8: ='Investment Analysis'!LL7 | EL8: ='Investment Analysis'!LS7 | EO8: ='Investment Analysis'!LZ7 | ER8: ='Investment Analysis'!KX7 | EU8: ='Investment Analysis'!MG7 | EX8: ='Investment Analysis'!MN7 | FA8: ='Investment Analysis'!MU7 | FD8: ='Investment Analysis'!NB7 | FG8: ='Investment Analysis'!NI7 | FJ8: ='Investment Analysis'!NP7 | FM8: ='Investment Analysis'!NW7 | FP8: ='Investment Analysis'!OD7 | FS8: ='Investment Analysis'!OK7 | FV8: ='Investment Analysis'!OR7 | FY8: ='Investment Analysis'!OY7 | GB8: ='Investment Analysis'!PF7 | GE8: ='Investment Analysis'!PT7 | GH8: ='Investment Analysis'!QA7 | GK8: ='Investment Analysis'!QH7 | GN8: ='Investment Analysis'!QO7 | GQ8: ='Investment Analysis'!QV7 | GT8: ='Investment Analysis'!RC7 | GW8: ='Investment Analysis'!RJ7 | GZ8: ='Investment Analysis'!RQ7 | HC8: ='Investment Analysis'!RX7 | HF8: ='Investment Analysis'!SE7 | HI8: ='Investment Analysis'!SL7 | HL8: ='Investment Analysis'!SS7 | HO8: ='Investment Analysis'!SZ7 | HR8: ='Investment Analysis'!TG7 | HU8: ='Investment Analysis'!TN7 | HX8: ='Investment Analysis'!TU7 | IA8: ='Investment Analysis'!UB7 | ID8: ='Investment Analysis'!UI7 | IG8: ='Investment Analysis'!UP7 | IJ8: ='Investment Analysis'!UW7 | IM8: ='Investment Analysis'!VD7 | IS8: =I2 | IT8: ='Investment Analysis'!VM6
D9: Value | E9: % | G9: Value | H9: % | J9: Value | K9: % | L9: Index | M9: Index | N9: Market | P9: ='Investment Analysis'!Y8 | Q9: % Change | R9: % Change | S9: ='Investment Analysis'!AC8 | T9: % Change | U9: % Change | V9: ='Investment Analysis'!AJ8 | W9: % Change | X9: % Change | Y9: FBIOX | Z9: % Change | AA9: % Change | AB9: ='Investment Analysis'!AQ8 | AC9: % Change | AD9: % Change | AE9: ='Investment Analysis'!AX8 | AF9: % Change | AG9: % Change | AH9: ='Investment Analysis'!BE8 | AI9: % Change | AJ9: % Change | AK9: ='Investment Analysis'!BL8 | AL9: % Change | AM9: % Change | AN9: ='Investment Analysis'!BS8 | AO9: % Change | AP9: % Change | AQ9: ='Investment Analysis'!GO8 | AR9: % Change | AS9: % Change | AT9: ='Investment Analysis'!CG8 | AU9: % Change | AV9: % Change | AW9: ='Investment Analysis'!CN8 | AX9: % Change | AY9: % Change | AZ9: ='Investment Analysis'!CU8 | BA9: % Change | BB9: % Change | BC9: ='Investment Analysis'!DB8 | BD9: % Change | BE9: % Change | BF9: ='Investment Analysis'!DI8 | BG9: % Change | BH9: % Change | BI9: ='Investment Analysis'!DW8 | BJ9: % Change | BK9: % Change | BL9: ='Investment Analysis'!ED8 | BM9: % Change | BN9: % Change | BO9: ='Investment Analysis'!DP8 | BP9: % Change | BQ9: % Change | BR9: ='Investment Analysis'!EK8 | BS9: % Change | BT9: % Change | BU9: ='Investment Analysis'!ER8 | BV9: % Change | BW9: % Change | BX9: ='Investment Analysis'!EY8 | BY9: % Change | BZ9: % Change | CA9: ='Investment Analysis'!FF8 | CB9: % Change | CC9: % Change | CD9: ='Investment Analysis'!FM8 | CE9: % Change | CF9: % Change | CG9: ='Investment Analysis'!FT8 | CH9: % Change | CI9: % Change | CJ9: ='Investment Analysis'!GA8 | CK9: % Change | CL9: % Change | CM9: ='Investment Analysis'!GV8 | CN9: % Change | CO9: % Change | CP9: ='Investment Analysis'!HD8 | CQ9: % Change | CR9: % Change | CS9: ='Investment Analysis'!HK8 | CT9: % Change | CU9: % Change | CV9: ='Investment Analysis'!HY8 | CW9: % Change | CX9: % Change | CY9: ='Investment Analysis'!IF8 | CZ9: % Change | DA9: % Change | DB9: ='Investment Analysis'!IM8 | DC9: % Change | DD9: % Change | DE9: ='Investment Analysis'!IT8 | DF9: % Change | DG9: % Change | DH9: ='Investment Analysis'!JA8 | DI9: % Change | DJ9: % Change | DK9: ='Investment Analysis'!JH8 | DL9: % Change | DM9: % Change | DN9: ='Investment Analysis'!HR8 | DO9: % Change | DP9: % Change | DQ9: ='Investment Analysis'!JO8 | DR9: % Change | DS9: % Change | DT9: ='Investment Analysis'!JV8 | DU9: % Change | DV9: % Change | DW9: ='Investment Analysis'!KC8 | DX9: % Change | DY9: % Change | DZ9: ='Investment Analysis'!KJ8 | EA9: % Change | EB9: % Change | EC9: ='Investment Analysis'!KQ8 | ED9: % Change | EE9: % Change | EF9: ='Investment Analysis'!LE8 | EG9: % Change | EH9: % Change | EI9: ='Investment Analysis'!LL8 | EJ9: % Change | EK9: % Change | EL9: ='Investment Analysis'!LS8 | EM9: % Change | EN9: % Change | EO9: ='Investment Analysis'!LZ8 | EP9: % Change | EQ9: % Change | ER9: ='Investment Analysis'!KX8 | ES9: % Change | ET9: % Change | EU9: ='Investment Analysis'!MG8 | EV9: % Change | EW9: % Change | EX9: ='Investment Analysis'!MN8 | EY9: % Change | EZ9: % Change | FA9: ='Investment Analysis'!MU8 | FB9: % Change | FC9: % Change | FD9: ='Investment Analysis'!NB8 | FE9: % Change | FF9: % Change | FG9: ='Investment Analysis'!NI8 | FH9: % Change | FI9: % Change | FJ9: ='Investment Analysis'!NP8 | FK9: % Change | FL9: % Change | FM9: ='Investment Analysis'!NW8 | FN9: % Change | FO9: % Change | FP9: ='Investment Analysis'!OD8 | FQ9: % Change | FR9: % Change | FS9: ='Investment Analysis'!OK8 | FT9: % Change | FU9: % Change | FV9: ='Investment Analysis'!OR8 | FW9: % Change | FX9: % Change | FY9: ='Investment Analysis'!OY8 | FZ9: % Change | GA9: % Change | GB9: ='Investment Analysis'!PF8 | GC9: % Change | GD9: % Change | GE9: ='Investment Analysis'!PT8 | GF9: % Change | GG9: % Change | GH9: ='Investment Analysis'!QA8 | GI9: % Change | GJ9: % Change | GK9: ='Investment Analysis'!QH8 | GL9: % Change | GM9: % Change | GN9: ='Investment Analysis'!QO8 | GO9: % Change | GP9: % Change | GQ9: ='Investment Analysis'!QV8 | GR9: % Change | GS9: % Change | GT9: ='Investment Analysis'!RC8 | GU9: % Change | GV9: % Change | GW9: ='Investment Analysis'!RJ8 | GX9: % Change | GY9: % Change | GZ9: ='Investment Analysis'!RQ8 | HA9: % Change | HB9: % Change | HC9: ='Investment Analysis'!RX8 | HD9: % Change | HE9: % Change | HF9: ='Investment Analysis'!SE8 | HG9: % Change | HH9: % Change | HI9: ='Investment Analysis'!SL8 | HJ9: % Change | HK9: % Change | HL9: ='Investment Analysis'!SS8 | HM9: % Change | HN9: % Change | HO9: ='Investment Analysis'!SZ8 | HP9: % Change | HQ9: % Change | HR9: ='Investment Analysis'!TG8 | HS9: % Change | HT9: % Change | HU9: ='Investment Analysis'!TN8 | HV9: % Change | HW9: % Change | HX9: VSLA | HY9: % Change | HZ9: % Change | IA9: ='Investment Analysis'!UB8:UB9 | IB9: % Change | IC9: % Change | ID9: ='Investment Analysis'!UI8:UI9 | IE9: % Change | IF9: % Change | IG9: ='Investment Analysis'!UP8:UP9 | IH9: % Change | II9: % Change | IJ9: =-'Investment Analysis'!UW8:UW9 | IK9: % Change | IL9: % Change | IM9: ='Investment Analysis'!VD8:VD9 | IN9: % Change | IO9: % Change | IS9: Daily | IT9: Portfolio | IU9: Dist. | IV9: Distribution | IW9: YTD % | IX9: YTD $ | IY9: % G/L | IZ9: $ G/L
A10: Date | B10: Day | C10: Value | D10: Gn/Ls | E10: Chang | F10: Value | G10: Gn/Ls | H10: Chang | I10: Value | J10: Gn/Ls | K10: Chang | L10: Avg | M10: Change | N10: Gain/Loss | Q10: YTD | R10: FromTrade | T10: YTD | U10: FromTrade | W10: YTD | X10: FromTrade | Z10: YTD | AA10: FromTrade | AC10: YTD | AD10: FromTrade | AF10: YTD | AG10: FromTrade | AI10: YTD | AJ10: FromTrade | AL10: YTD | AM10: FromTrade | AO10: YTD | AP10: FromTrade | AR10: YTD | AS10: FromTrade | AU10: YTD | AV10: FromTrade | AX10: YTD | AY10: FromTrade | BA10: YTD | BB10: FromTrade | BD10: YTD | BE10: FromTrade | BG10: YTD | BH10: FromTrade | BJ10: YTD | BK10: FromTrade | BM10: YTD | BN10: FromTrade | BP10: YTD | BQ10: FromTrade | BS10: YTD | BT10: FromTrade | BV10: YTD | BW10: FromTrade | BY10: YTD | BZ10: FromTrade | CB10: YTD | CC10: FromTrade | CE10: YTD | CF10: FromTrade | CH10: YTD | CI10: FromTrade | CK10: YTD | CL10: FromTrade | CN10: YTD | CO10: FromTrade | CQ10: YTD | CR10: FromTrade | CT10: YTD | CU10: FromTrade | CW10: YTD | CX10: FromTrade | CZ10: YTD | DA10: FromTrade | DC10: YTD | DD10: FromTrade | DF10: YTD | DG10: FromTrade | DI10: YTD | DJ10: FromTrade | DL10: YTD | DM10: FromTrade | DO10: YTD | DP10: FromTrade | DR10: YTD | DS10: FromTrade | DU10: YTD | DV10: FromTrade | DX10: YTD | DY10: FromTrade | EA10: YTD | EB10: FromTrade | ED10: YTD | EE10: FromTrade | EG10: YTD | EH10: FromTrade | EJ10: YTD | EK10: FromTrade | EM10: YTD | EN10: FromTrade | EP10: YTD | EQ10: FromTrade | ES10: YTD | ET10: FromTrade | EV10: YTD | EW10: FromTrade | EY10: YTD | EZ10: FromTrade | FB10: YTD | FC10: FromTrade | FE10: YTD | FF10: FromTrade | FH10: YTD | FI10: FromTrade | FK10: YTD | FL10: FromTrade | FN10: YTD | FO10: FromTrade | FQ10: YTD | FR10: FromTrade | FT10: YTD | FU10: FromTrade | FW10: YTD | FX10: FromTrade | FZ10: YTD | GA10: FromTrade | GC10: YTD | GD10: FromTrade | GF10: YTD | GG10: FromTrade | GI10: YTD | GJ10: FromTrade | GL10: YTD | GM10: FromTrade | GO10: YTD | GP10: FromTrade | GR10: YTD | GS10: FromTrade | GU10: YTD | GV10: FromTrade | GX10: YTD | GY10: FromTrade | HA10: YTD | HB10: FromTrade | HD10: YTD | HE10: FromTrade | HG10: YTD | HH10: FromTrade | HJ10: YTD | HK10: FromTrade | HM10: YTD | HN10: FromTrade | HP10: YTD | HQ10: FromTrade | HS10: YTD | HT10: FromTrade | HV10: YTD | HW10: FromTrade | HY10: YTD | HZ10: FromTrade | IB10: YTD | IC10: FromTrade | IE10: YTD | IF10: FromTrade | IH10: YTD | II10: FromTrade | IK10: YTD | IL10: FromTrade | IN10: YTD | IO10: FromTrade | IS10: Change | IT10: Value | IU10: Calc | IV10: Reduction | IW10: Gain/Loss | IX10: Gain/Loss | IY10: Fr. Trade | IZ10: Fr. Trade
A11: ='Investment Analysis'!A11 | B11: ='Investment Analysis'!B11 | C11: ='Investment Analysis'!C11 | D11: ='Investment Analysis'!D11 | E11: ='Investment Analysis'!E11 | F11: ='Investment Analysis'!G11 | G11: ='Investment Analysis'!H11 | H11: ='Investment Analysis'!I11 | I11: ='Investment Analysis'!K11 | J11: ='Investment Analysis'!L11 | K11: ='Investment Analysis'!M11 | L11: ='Investment Analysis'!T11 | M11: ='Investment Analysis'!V11 | N11: ='Investment Analysis'!W11 | P11: ='Investment Analysis'!Y11 | S11: 22394.73 | T11: =IF(S11>0,(S11-T$5)/T$5,0) | U11: ='Investment Analysis'!AF11 | V11: 17689.66 | W11: =IF(V11>0,(V11-W$5)/W$5,0) | X11: ='Investment Analysis'!AT11 | Y11: 9984.42 | Z11: =IF(Y11>0,(Y11-Z$5)/Z$5,0) | AA11: ='Investment Analysis'!GK11 | AB11: 2652.34 | AC11: =IF(AB11>0,(AB11-AC$5)/AC$5,0) | AD11: ='Investment Analysis'!AT11 | AE11: 22221.71 | AF11: =IF(AE11>0,(AE11-AF$5)/AF$5,0) | AG11: ='Investment Analysis'!BA11 | AI11: =IF(AH11>0,(AH11-AI$5)/AI$5,0) | AJ11: ='Investment Analysis'!BH11 | AK11: 18871.11 | AL11: =IF(AK11>0,(AK11-AL$5)/AL$5,0) | AM11: ='Investment Analysis'!BO11 | AN11: 14657.64 | AO11: =IF(AN11>0,(AN11-AO$5)/AO$5,0) | AP11: ='Investment Analysis'!BV11 | AR11: =IF(AQ11>0,(AQ11-AR$5)/AR$5,0) | AS11: ='Investment Analysis'!CC11 | AT11: 27039.97 | AU11: =IF(AT11>0,(AT11-AU$5)/AU$5,0) | AV11: ='Investment Analysis'!CJ11 | AW11: 19194.02 | AX11: =IF(AW11>0,(AW11-AX$5)/AX$5,0) | AY11: ='Investment Analysis'!CQ11 | AZ11: 16686.63 | BA11: =IF(AZ11>0,(AZ11-BA$5)/BA$5,0) | BB11: ='Investment Analysis'!CX11 | BC11: 9941.01 | BD11: =IF(BC11>0,(BC11-BD$5)/BD$5,0) | BE11: ='Investment Analysis'!DE11 | BF11: 4167.93 | BG11: =IF(BF11>0,(BF11-BG$5)/BG$5,0) | BH11: ='Investment Analysis'!DL11 | BI11: 2572.08 | BJ11: =IF(BI11>0,(BI11-BJ$5)/BJ$5,0) | BK11: ='Investment Analysis'!DZ11 | BL11: 4383.9 | BM11: =IF(BL11>0,(BL11-BM$5)/BM$5,0) | BN11: ='Investment Analysis'!EG11 | BP11: =IF(BO11>0,(BO11-BP$5)/BP$5,0) | BQ11: ='Investment Analysis'!DS11 | BR11: 5670.58 | BS11: =IF(BR11>0,(BR11-BS$5)/BS$5,0) | BT11: ='Investment Analysis'!EN11 | BU11: 14663.23 | BV11: =IF(BU11>0,(BU11-BV$5)/BV$5,0) | BW11: ='Investment Analysis'!EU11 | BY11: =IF(BX11>0,(BX11-BY$5)/BY$5,0) | BZ11: ='Investment Analysis'!FB11 | CA11: 3213.05 | CB11: =IF(CA11>0,(CA11-CB$5)/CB$5,0) | CC11: ='Investment Analysis'!FI11 | CD11: 18997.59 | CE11: =IF(CD11>0,(CD11-CE$5)/CE$5,0) | CF11: ='Investment Analysis'!FP11 | CG11: 5006.94 | CH11: =IF(CG11>0,(CG11-CH$5)/CH$5,0) | CI11: ='Investment Analysis'!FW11 | CK11: =IF(CJ11>0,(CJ11-CK$5)/CK$5,0) | CL11: ='Investment Analysis'!GD11 | CM11: 4964.99 | CN11: =IF(CM11>0,(CM11-CN$5)/CN$5,0) | CO11: ='Investment Analysis'!GT11 | CP11: 56892 | CQ11: =IF(CP11>0,(CP11-CQ$5)/CQ$5,0) | CR11: ='Investment Analysis'!HG11 | CS11: 6930 | CT11: =IF(CS11>0,(CS11-CT$5)/CT$5,0) | CU11: ='Investment Analysis'!HN11 | CW11: =IF(CV11>0,(CV11-CW$5)/CW$5,0) | CX11: ='Investment Analysis'!IB11 | CY11: 4639.6 | CZ11: =IF(CY11>0,(CY11-CZ$5)/CZ$5,0) | DA11: ='Investment Analysis'!II11 | DB11: 22092 | DC11: =IF(DB11>0,(DB11-DC$5)/DC$5,0) | DD11: ='Investment Analysis'!IP11 | DF11: =IF(DE11>0,(DE11-DF$5)/DF$5,0) | DG11: ='Investment Analysis'!IW11 | DH11: 2996.2 | DI11: =IF(DH11>0,(DH11-DI$5)/DI$5,0) | DJ11: ='Investment Analysis'!JD11 | DK11: 2092.9 | DL11: =IF(DK11>0,(DK11-DL$5)/DL$5,0) | DM11: ='Investment Analysis'!JK11 | DN11: 5365.5 | DO11: =IF(DN11>0,(DN11-DO$5)/DO$5,0) | DP11: ='Investment Analysis'!HU11 | DQ11: 23687.5 | DR11: =IF(DQ11>0,(DQ11-DR$5)/DR$5,0) | DS11: ='Investment Analysis'!JR11 | DT11: 3542 | DU11: =IF(DT11>0,(DT11-DU$5)/DU$5,0) | DV11: ='Investment Analysis'!JY11 | DW11: 22745.25 | DX11: =IF(DW11>0,(DW11-DX$5)/DX$5,0) | DY11: ='Investment Analysis'!KF11 | DZ11: 2311.2 | EA11: =IF(DZ11>0,(DZ11-EA$5)/EA$5,0) | EB11: ='Investment Analysis'!KM11 | EC11: 2438.5 | ED11: =IF(EC11>0,(EC11-ED$5)/ED$5,0) | EE11: ='Investment Analysis'!KT11 | EF11: 35512.5 | EG11: =IF(EF11>0,(EF11-EG$5)/EG$5,0) | EH11: ='Investment Analysis'!LH11 | EI11: 7625.07 | EJ11: =IF(EI11>0,(EI11-EJ$5)/EJ$5,0) | EK11: ='Investment Analysis'!LO11 | EM11: =IF(EL11>0,(EL11-EM$5)/EM$5,0) | EN11: ='Investment Analysis'!LV11 | EP11: =IF(EO11>0,(EO11-EP$5)/EP$5,0) | EQ11: ='Investment Analysis'!MC11 | ER11: 24249.82 | ES11: =IF(ER11>0,(ER11-ES$5)/ES$5,0) | ET11: ='Investment Analysis'!LA11 | EU11: 30590 | EV11: ='Investment Analysis'!ML11 | EW11: ='Investment Analysis'!MJ11 | EX11: 39018 | EY11: =IF(EX11>0,(EX11-EY$5)/EY$5,0) | EZ11: ='Investment Analysis'!MQ11 | FB11: =IF(FA11>0,(FA11-FB$5)/FB$5,0) | FC11: ='Investment Analysis'!MX11 | FD11: 4214.75 | FE11: =IF(FD11>0,(FD11-FE$5)/FE$5,0) | FF11: ='Investment Analysis'!NE11 | FH11: =IF(FG11>0,(FG11-FH$5)/FH$5,0) | FI11: ='Investment Analysis'!NL11 | FJ11: 8473.5 | FK11: =IF(FJ11>0,(FJ11-FK$5)/FK$5,0) | FL11: ='Investment Analysis'!NS11 | FM11: 30308.8 | FN11: =IF(FM11>0,(FM11-FN$5)/FN$5,0) | FO11: ='Investment Analysis'!NZ11 | FQ11: =IF(FP11>0,(FP11-FQ$5)/FQ$5,0) | FR11: ='Investment Analysis'!OG11 | FS11: 35173.75 | FT11: =IF(FS11>0,(FS11-FT$5)/FT$5,0) | FU11: ='Investment Analysis'!ON11 | FW11: =IF(FV11>0,(FV11-FW$5)/FW$5,0) | FX11: ='Investment Analysis'!OU11 | FZ11: =IF(FY11>0,(FY11-FZ$5)/FZ$5,0) | GC11: ='Investment Analysis'!PK11 | GD11: ='Investment Analysis'!PI11 | GE11: 6727 | GF11: ='Investment Analysis'!PY11 | GG11: ='Investment Analysis'!PW11 | GH11: 25175 | GI11: ='Investment Analysis'!QF11 | GJ11: ='Investment Analysis'!QD11 | GK11: 24220 | GL11: ='Investment Analysis'!QM11 | GM11: ='Investment Analysis'!QK11 | GN11: 9440.64 | GO11: ='Investment Analysis'!QT11 | GP11: ='Investment Analysis'!QR11 | GQ11: 17130.65 | GR11: ='Investment Analysis'!RA11 | GS11: ='Investment Analysis'!QY11 | GT11: 14966 | GU11: ='Investment Analysis'!RH11 | GV11: ='Investment Analysis'!RF11 | GX11: ='Investment Analysis'!RO11 | GY11: ='Investment Analysis'!RM11 | HA11: ='Investment Analysis'!RV11 | HB11: ='Investment Analysis'!RT11 | HD11: ='Investment Analysis'!SC11 | HE11: ='Investment Analysis'!SA11 | HG11: ='Investment Analysis'!SJ11 | HH11: ='Investment Analysis'!SH11 | HJ11: ='Investment Analysis'!SM11 | HK11: ='Investment Analysis'!SK11 | HM11: ='Investment Analysis'!SP11 | HN11: ='Investment Analysis'!SN11 | HP11: ='Investment Analysis'!TE11 | HQ11: ='Investment Analysis'!TC11 | HS11: ='Investment Analysis'!TL11 | HT11: ='Investment Analysis'!TJ11 | HV11: ='Investment Analysis'!TS11 | HW11: ='Investment Analysis'!TQ11 | HY11: ='Investment Analysis'!TZ11 | HZ11: ='Investment Analysis'!TX11 | IB11: ='Investment Analysis'!UG11 | IC11: ='Investment Analysis'!UE11 | IE11: ='Investment Analysis'!UN11 | IF11: ='Investment Analysis'!UL11 | IH11: ='Investment Analysis'!UU11 | II11: ='Investment Analysis'!US11 | IK11: ='Investment Analysis'!VB11 | IL11: ='Investment Analysis'!UZ11 | IN11: ='Investment Analysis'!VI11 | IO11: ='Investment Analysis'!VG11 | IS11: =IF(IT11>0,IT11-IS8,0) | IT11: =FY11+FV11+FS11+FP11+FM11+FJ11+FG11+FD11+FA11+EX11+EU11+ER11+EO11+EL11+EI11+EF11+EC11+DZ11+DW11+DT11+DQ11+DN11+DK11+DH11+DE11+DB11+CY11+CV11+CS11+CP11+CJ11+CG11+CD11+CA11+BX11+P11+CM11+GT11+GQ11+GN11+GK11+GH11+GE11+GB11+BU11+BR11+BO11+BL11+BI11+BF11+BC11+AZ11+AW11+AT11+AQ11+AN11+AK11+AH11+AE11+AB11+Y11+V11+S11+GW11+GZ11+HC11+HF11+HI11+HL11+HO11+HR11+HU11 | IU11: =IF(IT11>0,IV11,0) | IW11: =IF(IT11>0,(IT11+IV$11-I$2)/I$2,0) | IX11: =IF(IT11>0,IT11+IV$11-I$2,0) | IY11: =IF(IT11>0,(IT11+IV$11-IT$8)/IT$8,0) | IZ11: =IF(IT11>0,IT11+IV$11-IT$8,0)
A12: ='Investment Analysis'!A12 | B12: ='Investment Analysis'!B12 | C12: ='Investment Analysis'!C12 | D12: ='Investment Analysis'!D12 | E12: ='Investment Analysis'!E12 | F12: ='Investment Analysis'!G12 | G12: ='Investment Analysis'!H12 | H12: ='Investment Analysis'!I12 | I12: ='Investment Analysis'!K12 | J12: ='Investment Analysis'!L12 | K12: ='Investment Analysis'!M12 | L12: ='Investment Analysis'!T12 | M12: ='Investment Analysis'!V12 | N12: ='Investment Analysis'!W12 | P12: ='Investment Analysis'!Y12 | S12: 22807.18 | T12: =IF(S12>0,(S12-T$5)/T$5,0) | U12: ='Investment Analysis'!AF12 | V12: 17932.22 | W12: =IF(V12>0,(V12-W$5)/W$5,0) | X12: ='Investment Analysis'!AT12 | Y12: 10073.52 | Z12: =IF(Y12>0,(Y12-Z$5)/Z$5,0) | AA12: ='Investment Analysis'!GK12 | AB12: 2696.67 | AC12: =IF(AB12>0,(AB12-AC$5)/AC$5,0) | AD12: ='Investment Analysis'!AT12 | AE12: 22503.11 | AF12: =IF(AE12>0,(AE12-AF$5)/AF$5,0) | AG12: ='Investment Analysis'!BA12 | AI12: =IF(AH12>0,(AH12-AI$5)/AI$5,0) | AJ12: ='Investment Analysis'!BH12 | AK12: 19310.96 | AL12: =IF(AK12>0,(AK12-AL$5)/AL$5,0) | AM12: ='Investment Analysis'!BO12 | AN12: 14988.26 | AO12: =IF(AN12>0,(AN12-AO$5)/AO$5,0) | AP12: ='Investment Analysis'!BV12 | AR12: =IF(AQ12>0,(AQ12-AR$5)/AR$5,0) | AS12: ='Investment Analysis'!CC12 | AT12: 27535.62 | AU12: =IF(AT12>0,(AT12-AU$5)/AU$5,0) | AV12: ='Investment Analysis'!CJ12 | AW12: 19576.53 | AX12: =IF(AW12>0,(AW12-AX$5)/AX$5,0) | AY12: ='Investment Analysis'!CQ12 | AZ12: 16928.66 | BA12: =IF(AZ12>0,(AZ12-BA$5)/BA$5,0) | BB12: ='Investment Analysis'!CX12 | BC12: 10092.82 | BD12: =IF(BC12>0,(BC12-BD$5)/BD$5,0) | BE12: ='Investment Analysis'!DE12 | BF12: 4179.78 | BG12: =IF(BF12>0,(BF12-BG$5)/BG$5,0) | BH12: ='Investment Analysis'!DL12 | BI12: 2650.11 | BJ12: =IF(BI12>0,(BI12-BJ$5)/BJ$5,0) | BK12: ='Investment Analysis'!DZ12 | BL12: 4477.51 | BM12: =IF(BL12>0,(BL12-BM$5)/BM$5,0) | BN12: ='Investment Analysis'!EG12 | BP12: =IF(BO12>0,(BO12-BP$5)/BP$5,0) | BQ12: ='Investment Analysis'!DS12 | BR12: 5737.73 | BS12: =IF(BR12>0,(BR12-BS$5)/BS$5,0) | BT12: ='Investment Analysis'!EN12 | BU12: 14841.54 | BV12: =IF(BU12>0,(BU12-BV$5)/BV$5,0) | BW12: ='Investment Analysis'!EU12 | BY12: =IF(BX12>0,(BX12-BY$5)/BY$5,0) | BZ12: ='Investment Analysis'!FB12 | CA12: 3246.62 | CB12: =IF(CA12>0,(CA12-CB$5)/CB$5,0) | CC12: ='Investment Analysis'!FI12 | CD12: 19260.78 | CE12: =IF(CD12>0,(CD12-CE$5)/CE$5,0) | CF12: ='Investment Analysis'!FP12 | CG12: 5029.86 | CH12: =IF(CG12>0,(CG12-CH$5)/CH$5,0) | CI12: ='Investment Analysis'!FW12 | CK12: =IF(CJ12>0,(CJ12-CK$5)/CK$5,0) | CL12: ='Investment Analysis'!GD12 | CM12: 5018.73 | CN12: =IF(CM12>0,(CM12-CN$5)/CN$5,0) | CO12: ='Investment Analysis'!GT12 | CP12: 61566 | CQ12: =IF(CP12>0,(CP12-CQ$5)/CQ$5,0) | CR12: ='Investment Analysis'!HG12 | CS12: 7080 | CT12: =IF(CS12>0,(CS12-CT$5)/CT$5,0) | CU12: ='Investment Analysis'!HN12 | CW12: =IF(CV12>0,(CV12-CW$5)/CW$5,0) | CX12: ='Investment Analysis'!IB12 | CY12: 4651 | CZ12: =IF(CY12>0,(CY12-CZ$5)/CZ$5,0) | DA12: ='Investment Analysis'!II12 | DB12: 22215.2 | DC12: =IF(DB12>0,(DB12-DC$5)/DC$5,0) | DD12: ='Investment Analysis'!IP12 | DF12: =IF(DE12>0,(DE12-DF$5)/DF$5,0) | DG12: ='Investment Analysis'!IW12 | DH12: 3023.15 | DI12: =IF(DH12>0,(DH12-DI$5)/DI$5,0) | DJ12: ='Investment Analysis'!JD12 | DK12: 2116.75 | DL12: =IF(DK12>0,(DK12-DL$5)/DL$5,0) | DM12: ='Investment Analysis'!JK12 | DN12: 5393 | DO12: =IF(DN12>0,(DN12-DO$5)/DO$5,0) | DP12: ='Investment Analysis'!HU12 | DQ12: 24367.5 | DR12: =IF(DQ12>0,(DQ12-DR$5)/DR$5,0) | DS12: ='Investment Analysis'!JR12 | DT12: 4170 | DU12: =IF(DT12>0,(DT12-DU$5)/DU$5,0) | DV12: ='Investment Analysis'!JY12 | DW12: 22914.5 | DX12: =IF(DW12>0,(DW12-DX$5)/DX$5,0) | DY12: ='Investment Analysis'!KF12 | DZ12: 2300.4 | EA12: =IF(DZ12>0,(DZ12-EA$5)/EA$5,0) | EB12: ='Investment Analysis'!KM12 | EC12: 2433.6 | ED12: =IF(EC12>0,(EC12-ED$5)/ED$5,0) | EE12: ='Investment Analysis'!KT12 | EF12: 35265 | EG12: =IF(EF12>0,(EF12-EG$5)/EG$5,0) | EH12: ='Investment Analysis'!LH12 | EI12: 7540.44 | EJ12: =IF(EI12>0,(EI12-EJ$5)/EJ$5,0) | EK12: ='Investment Analysis'!LO12 | EM12: =IF(EL12>0,(EL12-EM$5)/EM$5,0) | EN12: ='Investment Analysis'!LV12 | EP12: =IF(EO12>0,(EO12-EP$5)/EP$5,0) | EQ12: ='Investment Analysis'!MC12 | ER12: 24696.71 | ES12: =IF(ER12>0,(ER12-ES$5)/ES$5,0) | ET12: ='Investment Analysis'!LA12 | EU12: 38150 | EV12: ='Investment Analysis'!ML12 | EW12: ='Investment Analysis'!MJ12 | EX12: 39725 | EY12: =IF(EX12>0,(EX12-EY$5)/EY$5,0) | EZ12: ='Investment Analysis'!MQ12 | FB12: =IF(FA12>0,(FA12-FB$5)/FB$5,0) | FC12: ='Investment Analysis'!MX12 | FD12: 4299 | FE12: =IF(FD12>0,(FD12-FE$5)/FE$5,0) | FF12: ='Investment Analysis'!NE12 | FH12: =IF(FG12>0,(FG12-FH$5)/FH$5,0) | FI12: ='Investment Analysis'!NL12 | FJ12: 8850.75 | FK12: =IF(FJ12>0,(FJ12-FK$5)/FK$5,0) | FL12: ='Investment Analysis'!NS12 | FM12: 30686.4 | FN12: =IF(FM12>0,(FM12-FN$5)/FN$5,0) | FO12: ='Investment Analysis'!NZ12 | FQ12: =IF(FP12>0,(FP12-FQ$5)/FQ$5,0) | FR12: ='Investment Analysis'!OG12 | FS12: 38380 | FT12: =IF(FS12>0,(FS12-FT$5)/FT$5,0) | FU12: ='Investment Analysis'!ON12 | FW12: =IF(FV12>0,(FV12-FW$5)/FW$5,0) | FX12: ='Investment Analysis'!OU12 | FZ12: =IF(FY12>0,(FY12-FZ$5)/FZ$5,0) | GA12: ='Investment Analysis'!PB12 | GC12: ='Investment Analysis'!PK12 | GD12: ='Investment Analysis'!PI12 | GE12: 6722 | GF12: ='Investment Analysis'!PY12 | GG12: ='Investment Analysis'!PW12 | GH12: 25436 | GI12: ='Investment Analysis'!QF12 | GJ12: ='Investment Analysis'!QD12 | GK12: 24404 | GL12: ='Investment Analysis'!QM12 | GM12: ='Investment Analysis'!QK12 | GN12: 9688.24 | GO12: ='Investment Analysis'!QT12 | GP12: ='Investment Analysis'!QR12 | GQ12: 16974.3 | GR12: ='Investment Analysis'!RA12 | GS12: ='Investment Analysis'!QY12 | GT12: 16236 | GU12: ='Investment Analysis'!RH12 | GV12: ='Investment Analysis'!RF12 | GX12: ='Investment Analysis'!RO12 | GY12: ='Investment Analysis'!RM12 | HA12: ='Investment Analysis'!RV12 | HB12: ='Investment Analysis'!RT12 | HD12: ='Investment Analysis'!SC12 | HE12: ='Investment Analysis'!SA12 | HG12: ='Investment Analysis'!SJ12 | HH12: ='Investment Analysis'!SH12 | HJ12: ='Investment Analysis'!SM12 | HK12: ='Investment Analysis'!SK12 | HM12: ='Investment Analysis'!SP12 | HN12: ='Investment Analysis'!SN12 | HO12: ='Investment Analysis'!SZ257 | HP12: ='Investment Analysis'!TE12 | HQ12: ='Investment Analysis'!TC12 | HS12: ='Investment Analysis'!TL12 | HT12: ='Investment Analysis'!TJ12 | HV12: ='Investment Analysis'!TS12 | HW12: ='Investment Analysis'!TQ12 | HY12: ='Investment Analysis'!TZ12 | HZ12: ='Investment Analysis'!TX12 | IB12: ='Investment Analysis'!UG12 | IC12: ='Investment Analysis'!UE12 | IE12: ='Investment Analysis'!UN12 | IF12: ='Investment Analysis'!UL12 | IH12: ='Investment Analysis'!UU12 | II12: ='Investment Analysis'!US12 | IK12: ='Investment Analysis'!VB12 | IL12: ='Investment Analysis'!UZ12 | IN12: ='Investment Analysis'!VI12 | IO12: ='Investment Analysis'!VG12 | IS12: =IF(IT12>0,IT12-IT11,0) | IT12: =FY12+FV12+FS12+FP12+FM12+FJ12+FG12+FD12+FA12+EX12+EU12+ER12+EO12+EL12+EI12+EF12+EC12+DZ12+DW12+DT12+DQ12+DN12+DK12+DH12+DE12+DB12+CY12+CV12+CS12+CP12+CJ12+CG12+CD12+CA12+BX12+P12+CM12+GT12+GQ12+GN12+GK12+GH12+GE12+GB12+BU12+BR12+BO12+BL12+BI12+BF12+BC12+AZ12+AW12+AT12+AQ12+AN12+AK12+AH12+AE12+AB12+Y12+V12+S12+GW12+GZ12+HC12+HF12+HI12+HL12+HO12+HR12+HU12+HX12+IA12+ID12+IG12+IJ12+IM12 | IU12: =IF(IT12>0,IV12,0) | IV12: 3600 | IW12: =IF(IT12>0,(IT12+IV$11-I$2)/I$2,0) | IX12: =IF(IT12>0,IT12+IV$11-I$2,0) | IY12: =IF(IT12>0,(IT12+IV$11-IT$8)/IT$8,0) | IZ12: =IF(IT12>0,IT12+IV$11-IT$8,0)
A13: ='Investment Analysis'!A13 | B13: ='Investment Analysis'!B13 | C13: ='Investment Analysis'!C13 | D13: ='Investment Analysis'!D13 | E13: ='Investment Analysis'!E13 | F13: ='Investment Analysis'!G13 | G13: ='Investment Analysis'!H13 | H13: ='Investment Analysis'!I13 | I13: ='Investment Analysis'!K13 | J13: ='Investment Analysis'!L13 | K13: ='Investment Analysis'!M13 | L13: ='Investment Analysis'!T13 | M13: ='Investment Analysis'!V13 | N13: ='Investment Analysis'!W13 | P13: ='Investment Analysis'!Y13 | S13: 23167.57 | T13: =IF(S13>0,(S13-T$5)/T$5,0) | U13: ='Investment Analysis'!AF13 | V13: 18174.77 | W13: =IF(V13>0,(V13-W$5)/W$5,0) | X13: ='Investment Analysis'!AT13 | Y13: 9979.18 | Z13: =IF(Y13>0,(Y13-Z$5)/Z$5,0) | AA13: ='Investment Analysis'!GK13 | AB13: 2742.23 | AC13: =IF(AB13>0,(AB13-AC$5)/AC$5,0) | AD13: ='Investment Analysis'!AT13 | AE13: 22629.63 | AF13: =IF(AE13>0,(AE13-AF$5)/AF$5,0) | AG13: ='Investment Analysis'!BA13 | AI13: =IF(AH13>0,(AH13-AI$5)/AI$5,0) | AJ13: ='Investment Analysis'!BH13 | AK13: 19327.87 | AL13: =IF(AK13>0,(AK13-AL$5)/AL$5,0) | AM13: ='Investment Analysis'!BO13 | AN13: 15201.08 | AO13: =IF(AN13>0,(AN13-AO$5)/AO$5,0) | AP13: ='Investment Analysis'!BV13 | AR13: =IF(AQ13>0,(AQ13-AR$5)/AR$5,0) | AS13: ='Investment Analysis'!CC13 | AT13: 27685.09 | AU13: =IF(AT13>0,(AT13-AU$5)/AU$5,0) | AV13: ='Investment Analysis'!CJ13 | AW13: 19610.79 | AX13: =IF(AW13>0,(AW13-AX$5)/AX$5,0) | AY13: ='Investment Analysis'!CQ13 | AZ13: 16973.48 | BA13: =IF(AZ13>0,(AZ13-BA$5)/BA$5,0) | BB13: ='Investment Analysis'!CX13 | BC13: 10102.61 | BD13: =IF(BC13>0,(BC13-BD$5)/BD$5,0) | BE13: ='Investment Analysis'!DE13 | BF13: 4231.17 | BG13: =IF(BF13>0,(BF13-BG$5)/BG$5,0) | BH13: ='Investment Analysis'!DL13 | BI13: 2734.97 | BJ13: =IF(BI13>0,(BI13-BJ$5)/BJ$5,0) | BK13: ='Investment Analysis'!DZ13 | BL13: 4565.18 | BM13: =IF(BL13>0,(BL13-BM$5)/BM$5,0) | BN13: ='Investment Analysis'!EG13 | BP13: =IF(BO13>0,(BO13-BP$5)/BP$5,0) | BQ13: ='Investment Analysis'!DS13 | BR13: 5866.47 | BS13: =IF(BR13>0,(BR13-BS$5)/BS$5,0) | BT13: ='Investment Analysis'!EN13 | BU13: 14796.01 | BV13: =IF(BU13>0,(BU13-BV$5)/BV$5,0) | BW13: ='Investment Analysis'!EU13 | BY13: =IF(BX13>0,(BX13-BY$5)/BY$5,0) | BZ13: ='Investment Analysis'!FB13 | CA13: 3252.78 | CB13: =IF(CA13>0,(CA13-CB$5)/CB$5,0) | CC13: ='Investment Analysis'!FI13 | CD13: 19226.45 | CE13: =IF(CD13>0,(CD13-CE$5)/CE$5,0) | CF13: ='Investment Analysis'!FP13 | CG13: 4977.87 | CH13: =IF(CG13>0,(CG13-CH$5)/CH$5,0) | CI13: ='Investment Analysis'!FW13 | CK13: =IF(CJ13>0,(CJ13-CK$5)/CK$5,0) | CL13: ='Investment Analysis'!GD13 | CM13: 5004.4 | CN13: =IF(CM13>0,(CM13-CN$5)/CN$5,0) | CO13: ='Investment Analysis'!GT13 | CP13: 61657.5 | CQ13: =IF(CP13>0,(CP13-CQ$5)/CQ$5,0) | CR13: ='Investment Analysis'!HG13 | CS13: 6930 | CT13: =IF(CS13>0,(CS13-CT$5)/CT$5,0) | CU13: ='Investment Analysis'!HN13 | CW13: =IF(CV13>0,(CV13-CW$5)/CW$5,0) | CX13: ='Investment Analysis'!IB13 | CY13: 4728.2 | CZ13: =IF(CY13>0,(CY13-CZ$5)/CZ$5,0) | DA13: ='Investment Analysis'!II13 | DB13: 22308.8 | DC13: =IF(DB13>0,(DB13-DC$5)/DC$5,0) | DD13: ='Investment Analysis'!IP13 | DF13: =IF(DE13>0,(DE13-DF$5)/DF$5,0) | DG13: ='Investment Analysis'!IW13 | DH13: 3151 | DI13: =IF(DH13>0,(DH13-DI$5)/DI$5,0) | DJ13: ='Investment Analysis'!JD13 | DK13: 2139.25 | DL13: =IF(DK13>0,(DK13-DL$5)/DL$5,0) | DM13: ='Investment Analysis'!JK13 | DN13: 5387 | DO13: =IF(DN13>0,(DN13-DO$5)/DO$5,0) | DP13: ='Investment Analysis'!HU13 | DQ13: 24485 | DR13: =IF(DQ13>0,(DQ13-DR$5)/DR$5,0) | DS13: ='Investment Analysis'!JR13 | DT13: 4732 | DU13: =IF(DT13>0,(DT13-DU$5)/DU$5,0) | DV13: ='Investment Analysis'!JY13 | DW13: 23067.75 | DX13: =IF(DW13>0,(DW13-DX$5)/DX$5,0) | DY13: ='Investment Analysis'!KF13 | DZ13: 2242.8 | EA13: =IF(DZ13>0,(DZ13-EA$5)/EA$5,0) | EB13: ='Investment Analysis'!KM13 | EC13: 2450 | ED13: =IF(EC13>0,(EC13-ED$5)/ED$5,0) | EE13: ='Investment Analysis'!KT13 | EF13: 35730 | EG13: =IF(EF13>0,(EF13-EG$5)/EG$5,0) | EH13: ='Investment Analysis'!LH13 | EI13: 7408.38 | EJ13: =IF(EI13>0,(EI13-EJ$5)/EJ$5,0) | EK13: ='Investment Analysis'!LO13 | EM13: =IF(EL13>0,(EL13-EM$5)/EM$5,0) | EN13: ='Investment Analysis'!LV13 | EP13: =IF(EO13>0,(EO13-EP$5)/EP$5,0) | EQ13: ='Investment Analysis'!MC13 | ER13: 24772.15 | ES13: =IF(ER13>0,(ER13-ES$5)/ES$5,0) | ET13: ='Investment Analysis'!LA13 | EU13: 42000 | EV13: ='Investment Analysis'!ML13 | EW13: ='Investment Analysis'!MJ13 | EX13: 40173 | EY13: =IF(EX13>0,(EX13-EY$5)/EY$5,0) | EZ13: ='Investment Analysis'!MQ13 | FB13: =IF(FA13>0,(FA13-FB$5)/FB$5,0) | FC13: ='Investment Analysis'!MX13 | FD13: 4311.25 | FE13: =IF(FD13>0,(FD13-FE$5)/FE$5,0) | FF13: ='Investment Analysis'!NE13 | FH13: =IF(FG13>0,(FG13-FH$5)/FH$5,0) | FI13: ='Investment Analysis'!NL13 | FJ13: 9283 | FK13: =IF(FJ13>0,(FJ13-FK$5)/FK$5,0) | FL13: ='Investment Analysis'!NS13 | FM13: 31499.2 | FN13: =IF(FM13>0,(FM13-FN$5)/FN$5,0) | FO13: ='Investment Analysis'!NZ13 | FQ13: =IF(FP13>0,(FP13-FQ$5)/FQ$5,0) | FR13: ='Investment Analysis'!OG13 | FS13: 38750.5 | FT13: =IF(FS13>0,(FS13-FT$5)/FT$5,0) | FU13: ='Investment Analysis'!ON13 | FW13: =IF(FV13>0,(FV13-FW$5)/FW$5,0) | FX13: ='Investment Analysis'!OU13 | FZ13: =IF(FY13>0,(FY13-FZ$5)/FZ$5,0) | GA13: ='Investment Analysis'!PB13 | GC13: ='Investment Analysis'!PK13 | GD13: ='Investment Analysis'!PI13 | GE13: 6627.5 | GF13: ='Investment Analysis'!PY13 | GG13: ='Investment Analysis'!PW13 | GH13: 25970 | GI13: ='Investment Analysis'!QF13 | GJ13: ='Investment Analysis'!QD13 | GK13: 24200 | GL13: ='Investment Analysis'!QM13 | GM13: ='Investment Analysis'!QK13 | GN13: 9813.04 | GO13: ='Investment Analysis'!QT13 | GP13: ='Investment Analysis'!QR13 | GQ13: 16649.8 | GR13: ='Investment Analysis'!RA13 | GS13: ='Investment Analysis'!QY13 | GT13: 16395 | GU13: ='Investment Analysis'!RH13 | GV13: ='Investment Analysis'!RF13 | GX13: ='Investment Analysis'!RO13 | GY13: ='Investment Analysis'!RM13 | HA13: ='Investment Analysis'!RV13 | HB13: ='Investment Analysis'!RT13 | HD13: ='Investment Analysis'!SC13 | HE13: ='Investment Analysis'!SA13 | HG13: ='Investment Analysis'!SJ13 | HH13: ='Investment Analysis'!SH13 | HJ13: ='Investment Analysis'!SM13 | HK13: ='Investment Analysis'!SK13 | HM13: ='Investment Analysis'!SP13 | HN13: ='Investment Analysis'!SN13 | HP13: ='Investment Analysis'!TE13 | HQ13: ='Investment Analysis'!TC13 | HS13: ='Investment Analysis'!TL13 | HT13: ='Investment Analysis'!TJ13 | HV13: ='Investment Analysis'!TS13 | HW13: ='Investment Analysis'!TQ13 | HY13: ='Investment Analysis'!TZ13 | HZ13: ='Investment Analysis'!TX13 | IB13: ='Investment Analysis'!UG13 | IC13: ='Investment Analysis'!UE13 | IE13: ='Investment Analysis'!UN13 | IF13: ='Investment Analysis'!UL13 | IH13: ='Investment Analysis'!UU13 | II13: ='Investment Analysis'!US13 | IK13: ='Investment Analysis'!VB13 | IL13: ='Investment Analysis'!UZ13 | IN13: ='Investment Analysis'!VI13 | IO13: ='Investment Analysis'!VG13 | IS13: =IF(IT13>0,IT13-IT12,0) | IT13: =FY13+FV13+FS13+FP13+FM13+FJ13+FG13+FD13+FA13+EX13+EU13+ER13+EO13+EL13+EI13+EF13+EC13+DZ13+DW13+DT13+DQ13+DN13+DK13+DH13+DE13+DB13+CY13+CV13+CS13+CP13+CJ13+CG13+CD13+CA13+BX13+P13+CM13+GT13+GQ13+GN13+GK13+GH13+GE13+GB13+BU13+BR13+BO13+BL13+BI13+BF13+BC13+AZ13+AW13+AT13+AQ13+AN13+AK13+AH13+AE13+AB13+Y13+V13+S13+GW13+GZ13+HC13+HF13+HI13+HL13+HO13+HR13+HU13 | IU13: =IF(IT13>0,IV13,0) | IW13: =IF(IT13>0,(IT13+IV$11-I$2)/I$2,0) | IX13: =IF(IT13>0,IT13+IV$11-I$2,0) | IY13: =IF(IT13>0,(IT13+IV$11-IT$8)/IT$8,0) | IZ13: =IF(IT13>0,IT13+IV$11-IT$8,0)
A14: ='Investment Analysis'!A14 | B14: ='Investment Analysis'!B14 | C14: ='Investment Analysis'!C14 | D14: ='Investment Analysis'!D14 | E14: ='Investment Analysis'!E14 | F14: ='Investment Analysis'!G14 | G14: ='Investment Analysis'!H14 | H14: ='Investment Analysis'!I14 | I14: ='Investment Analysis'!K14 | J14: ='Investment Analysis'!L14 | K14: ='Investment Analysis'!M14 | L14: ='Investment Analysis'!T14 | M14: ='Investment Analysis'!V14 | N14: ='Investment Analysis'!W14 | P14: ='Investment Analysis'!Y14 | S14: 22684.43 | T14: =IF(S14>0,(S14-T$5)/T$5,0) | U14: ='Investment Analysis'!AF14 | V14: 17932.22 | W14: =IF(V14>0,(V14-W$5)/W$5,0) | X14: ='Investment Analysis'!AT14 | Y14: 10052.56 | Z14: =IF(Y14>0,(Y14-Z$5)/Z$5,0) | AA14: ='Investment Analysis'!GK14 | AB14: 2690.52 | AC14: =IF(AB14>0,(AB14-AC$5)/AC$5,0) | AD14: ='Investment Analysis'!AT14 | AE14: 22378.77 | AF14: =IF(AE14>0,(AE14-AF$5)/AF$5,0) | AG14: ='Investment Analysis'!BA14 | AI14: =IF(AH14>0,(AH14-AI$5)/AI$5,0) | AJ14: ='Investment Analysis'!BH14 | AK14: 18975.43 | AL14: =IF(AK14>0,(AK14-AL$5)/AL$5,0) | AM14: ='Investment Analysis'!BO14 | AN14: 14954.06 | AO14: =IF(AN14>0,(AN14-AO$5)/AO$5,0) | AP14: ='Investment Analysis'!BV14 | AR14: =IF(AQ14>0,(AQ14-AR$5)/AR$5,0) | AS14: ='Investment Analysis'!CC14 | AT14: 27519.88 | AU14: =IF(AT14>0,(AT14-AU$5)/AU$5,0) | AV14: ='Investment Analysis'!CJ14 | AW14: 19450.93 | AX14: =IF(AW14>0,(AW14-AX$5)/AX$5,0) | AY14: ='Investment Analysis'!CQ14 | AZ14: 16874.88 | BA14: =IF(AZ14>0,(AZ14-BA$5)/BA$5,0) | BB14: ='Investment Analysis'!CX14 | BC14: 10058.54 | BD14: =IF(BC14>0,(BC14-BD$5)/BD$5,0) | BE14: ='Investment Analysis'!DE14 | BF14: 4219.31 | BG14: =IF(BF14>0,(BF14-BG$5)/BG$5,0) | BH14: ='Investment Analysis'!DL14 | BI14: 2657.69 | BJ14: =IF(BI14>0,(BI14-BJ$5)/BJ$5,0) | BK14: ='Investment Analysis'!DZ14 | BL14: 4447.88 | BM14: =IF(BL14>0,(BL14-BM$5)/BM$5,0) | BN14: ='Investment Analysis'!EG14 | BP14: =IF(BO14>0,(BO14-BP$5)/BP$5,0) | BQ14: ='Investment Analysis'!DS14 | BR14: 5776.1 | BS14: =IF(BR14>0,(BR14-BS$5)/BS$5,0) | BT14: ='Investment Analysis'!EN14 | BU14: 14640.46 | BV14: =IF(BU14>0,(BU14-BV$5)/BV$5,0) | BW14: ='Investment Analysis'!EU14 | BY14: =IF(BX14>0,(BX14-BY$5)/BY$5,0) | BZ14: ='Investment Analysis'!FB14 | CA14: 3285.79 | CB14: =IF(CA14>0,(CA14-CB$5)/CB$5,0) | CC14: ='Investment Analysis'!FI14 | CD14: 18864.43 | CE14: =IF(CD14>0,(CD14-CE$5)/CE$5,0) | CF14: ='Investment Analysis'!FP14 | CG14: 5004.7 | CH14: =IF(CG14>0,(CG14-CH$5)/CH$5,0) | CI14: ='Investment Analysis'!FW14 | CK14: =IF(CJ14>0,(CJ14-CK$5)/CK$5,0) | CL14: ='Investment Analysis'!GD14 | CM14: 4982.9 | CN14: =IF(CM14>0,(CM14-CN$5)/CN$5,0) | CO14: ='Investment Analysis'!GT14 | CP14: 59154 | CQ14: =IF(CP14>0,(CP14-CQ$5)/CQ$5,0) | CR14: ='Investment Analysis'!HG14 | CS14: 6960 | CT14: =IF(CS14>0,(CS14-CT$5)/CT$5,0) | CU14: ='Investment Analysis'!HN14 | CV14: 0 | CW14: =IF(CV14>0,(CV14-CW$5)/CW$5,0) | CX14: ='Investment Analysis'!IB14 | CY14: 4572.8 | CZ14: =IF(CY14>0,(CY14-CZ$5)/CZ$5,0) | DA14: ='Investment Analysis'!II14 | DB14: 21981.6 | DC14: =IF(DB14>0,(DB14-DC$5)/DC$5,0) | DD14: ='Investment Analysis'!IP14 | DF14: =IF(DE14>0,(DE14-DF$5)/DF$5,0) | DG14: ='Investment Analysis'!IW14 | DH14: 3089.45 | DI14: =IF(DH14>0,(DH14-DI$5)/DI$5,0) | DJ14: ='Investment Analysis'!JD14 | DK14: 2111.85 | DL14: =IF(DK14>0,(DK14-DL$5)/DL$5,0) | DM14: ='Investment Analysis'!JK14 | DN14: 5437.5 | DO14: =IF(DN14>0,(DN14-DO$5)/DO$5,0) | DP14: ='Investment Analysis'!HU14 | DQ14: 23982.5 | DR14: =IF(DQ14>0,(DQ14-DR$5)/DR$5,0) | DS14: ='Investment Analysis'!JR14 | DT14: 4344 | DU14: =IF(DT14>0,(DT14-DU$5)/DU$5,0) | DV14: ='Investment Analysis'!JY14 | DW14: 23034.25 | DX14: =IF(DW14>0,(DW14-DX$5)/DX$5,0) | DY14: ='Investment Analysis'!KF14 | DZ14: 2247.6 | EA14: =IF(DZ14>0,(DZ14-EA$5)/EA$5,0) | EB14: ='Investment Analysis'!KM14 | EC14: 2422.1 | ED14: =IF(EC14>0,(EC14-ED$5)/ED$5,0) | EE14: ='Investment Analysis'!KT14 | EF14: 36112.5 | EG14: =IF(EF14>0,(EF14-EG$5)/EG$5,0) | EH14: ='Investment Analysis'!LH14 | EI14: 7546.95 | EJ14: =IF(EI14>0,(EI14-EJ$5)/EJ$5,0) | EK14: ='Investment Analysis'!LO14 | EM14: =IF(EL14>0,(EL14-EM$5)/EM$5,0) | EN14: ='Investment Analysis'!LV14 | EP14: =IF(EO14>0,(EO14-EP$5)/EP$5,0) | EQ14: ='Investment Analysis'!MC14 | ER14: 24245.45 | ES14: =IF(ER14>0,(ER14-ES$5)/ES$5,0) | ET14: ='Investment Analysis'!LA14 | EU14: 41300 | EV14: ='Investment Analysis'!ML14 | EW14: ='Investment Analysis'!MJ14 | EX14: 40295.5 | EY14: =IF(EX14>0,(EX14-EY$5)/EY$5,0) | EZ14: ='Investment Analysis'!MQ14 | FB14: =IF(FA14>0,(FA14-FB$5)/FB$5,0) | FC14: ='Investment Analysis'!MX14 | FD14: 4307.75 | FE14: =IF(FD14>0,(FD14-FE$5)/FE$5,0) | FF14: ='Investment Analysis'!NE14 | FH14: =IF(FG14>0,(FG14-FH$5)/FH$5,0) | FI14: ='Investment Analysis'!NL14 | FJ14: 9213 | FK14: =IF(FJ14>0,(FJ14-FK$5)/FK$5,0) | FL14: ='Investment Analysis'!NS14 | FM14: 31278.4 | FN14: =IF(FM14>0,(FM14-FN$5)/FN$5,0) | FO14: ='Investment Analysis'!NZ14 | FQ14: =IF(FP14>0,(FP14-FQ$5)/FQ$5,0) | FR14: ='Investment Analysis'!OG14 | FS14: 34983.75 | FT14: =IF(FS14>0,(FS14-FT$5)/FT$5,0) | FU14: ='Investment Analysis'!ON14 | FW14: =IF(FV14>0,(FV14-FW$5)/FW$5,0) | FX14: ='Investment Analysis'!OU14 | FZ14: =IF(FY14>0,(FY14-FZ$5)/FZ$5,0) | GA14: ='Investment Analysis'!PB14 | GC14: ='Investment Analysis'!PK14 | GD14: ='Investment Analysis'!PI14 | GE14: 6681.5 | GF14: ='Investment Analysis'!PY14 | GG14: ='Investment Analysis'!PW14 | GH14: 25729 | GI14: ='Investment Analysis'!QF14 | GJ14: ='Investment Analysis'!QD14 | GK14: 24280 | GL14: ='Investment Analysis'!QM14 | GM14: ='Investment Analysis'!QK14 | GN14: 10066.32 | GO14: ='Investment Analysis'!QT14 | GP14: ='Investment Analysis'!QR14 | GQ14: 16767.8 | GR14: ='Investment Analysis'!RA14 | GS14: ='Investment Analysis'!QY14 | GT14: 16337 | GU14: ='Investment Analysis'!RH14 | GV14: ='Investment Analysis'!RF14 | GX14: ='Investment Analysis'!RO14 | GY14: ='Investment Analysis'!RM14 | HA14: ='Investment Analysis'!RV14 | HB14: ='Investment Analysis'!RT14 | HD14: ='Investment Analysis'!SC14 | HE14: ='Investment Analysis'!SA14 | HG14: ='Investment Analysis'!SJ14 | HH14: ='Investment Analysis'!SH14 | HJ14: ='Investment Analysis'!SM14 | HK14: ='Investment Analysis'!SK14 | HM14: ='Investment Analysis'!SP14 | HN14: ='Investment Analysis'!SN14 | HP14: ='Investment Analysis'!TE14 | HQ14: ='Investment Analysis'!TC14 | HS14: ='Investment Analysis'!TL14 | HT14: ='Investment Analysis'!TJ14 | HV14: ='Investment Analysis'!TS14 | HW14: ='Investment Analysis'!TQ14 | HY14: ='Investment Analysis'!TZ14 | HZ14: ='Investment Analysis'!TX14 | IB14: ='Investment Analysis'!UG14 | IC14: ='Investment Analysis'!UE14 | IE14: ='Investment Analysis'!UN14 | IF14: ='Investment Analysis'!UL14 | IH14: ='Investment Analysis'!UU14 | II14: ='Investment Analysis'!US14 | IK14: ='Investment Analysis'!VB14 | IL14: ='Investment Analysis'!UZ14 | IN14: ='Investment Analysis'!VI14 | IO14: ='Investment Analysis'!VG14 | IS14: =IF(IT14>0,IT14-IT13,0) | IT14: =FY14+FV14+FS14+FP14+FM14+FJ14+FG14+FD14+FA14+EX14+EU14+ER14+EO14+EL14+EI14+EF14+EC14+DZ14+DW14+DT14+DQ14+DN14+DK14+DH14+DE14+DB14+CY14+CV14+CS14+CP14+CJ14+CG14+CD14+CA14+BX14+P14+CM14+GT14+GQ14+GN14+GK14+GH14+GE14+GB14+BU14+BR14+BO14+BL14+BI14+BF14+BC14+AZ14+AW14+AT14+AQ14+AN14+AK14+AH14+AE14+AB14+Y14+V14+S14+GW14+GZ14+HC14+HF14+HI14+HL14+HO14+HR14+HU14 | IU14: =IF(IT14>0,IV14,0) | IW14: =IF(IT14>0,(IT14+IV$11-I$2)/I$2,0) | IX14: =IF(IT14>0,IT14+IV$11-I$2,0) | IY14: =IF(IT14>0,(IT14+IV$11-IT$8)/IT$8,0) | IZ14: =IF(IT14>0,IT14+IV$11-IT$8,0)
